[2024-02-27T05:08:18.695+0000] {taskinstance.py:1979} INFO - Dependencies all met for dep_context=non-requeueable deps ti=<TaskInstance: miai_dag.crawl_data manual__2024-02-27T05:03:00.262822+00:00 [queued]>
[2024-02-27T05:08:18.702+0000] {taskinstance.py:1979} INFO - Dependencies all met for dep_context=requeueable deps ti=<TaskInstance: miai_dag.crawl_data manual__2024-02-27T05:03:00.262822+00:00 [queued]>
[2024-02-27T05:08:18.710+0000] {taskinstance.py:2193} INFO - Starting attempt 2 of 2
[2024-02-27T05:08:18.721+0000] {taskinstance.py:2214} INFO - Executing <Task(PythonOperator): crawl_data> on 2024-02-27 05:03:00.262822+00:00
[2024-02-27T05:08:18.726+0000] {standard_task_runner.py:60} INFO - Started process 1527 to run task
[2024-02-27T05:08:18.730+0000] {standard_task_runner.py:87} INFO - Running: ['***', 'tasks', 'run', 'miai_dag', 'crawl_data', 'manual__2024-02-27T05:03:00.262822+00:00', '--job-id', '38', '--raw', '--subdir', 'DAGS_FOLDER/train.py', '--cfg-path', '/tmp/tmp8bcvx2t1']
[2024-02-27T05:08:18.735+0000] {standard_task_runner.py:88} INFO - Job 38: Subtask crawl_data
[2024-02-27T05:08:18.776+0000] {task_command.py:423} INFO - Running <TaskInstance: miai_dag.crawl_data manual__2024-02-27T05:03:00.262822+00:00 [running]> on host a4c4cdbc324d
[2024-02-27T05:08:18.833+0000] {taskinstance.py:2510} INFO - Exporting env vars: AIRFLOW_CTX_DAG_EMAIL='phuongthaoadn@gmail.com' AIRFLOW_CTX_DAG_OWNER='***' AIRFLOW_CTX_DAG_ID='miai_dag' AIRFLOW_CTX_TASK_ID='crawl_data' AIRFLOW_CTX_EXECUTION_DATE='2024-02-27T05:03:00.262822+00:00' AIRFLOW_CTX_TRY_NUMBER='2' AIRFLOW_CTX_DAG_RUN_ID='manual__2024-02-27T05:03:00.262822+00:00'
[2024-02-27T05:08:18.842+0000] {logging_mixin.py:188} INFO - https://finfo-api.vndirect.com.vn/v4/stock_prices?sort=date&q=code:DIG~date:gte:2000-01-01~date:lte:2024-02-27&size=9990&page=1
[2024-02-27T05:08:30.355+0000] {taskinstance.py:2728} ERROR - Task failed with exception
Traceback (most recent call last):
  File "/home/airflow/.local/lib/python3.11/site-packages/airflow/models/taskinstance.py", line 444, in _execute_task
    result = _execute_callable(context=context, **execute_callable_kwargs)
             ^^^^^^^^^^^^^^^^^^^^^^^^^^^^^^^^^^^^^^^^^^^^^^^^^^^^^^^^^^^^^
  File "/home/airflow/.local/lib/python3.11/site-packages/airflow/models/taskinstance.py", line 414, in _execute_callable
    return execute_callable(context=context, **execute_callable_kwargs)
           ^^^^^^^^^^^^^^^^^^^^^^^^^^^^^^^^^^^^^^^^^^^^^^^^^^^^^^^^^^^^
  File "/home/airflow/.local/lib/python3.11/site-packages/airflow/operators/python.py", line 200, in execute
    return_value = self.execute_callable()
                   ^^^^^^^^^^^^^^^^^^^^^^^
  File "/home/airflow/.local/lib/python3.11/site-packages/airflow/operators/python.py", line 217, in execute_callable
    return self.python_callable(*self.op_args, **self.op_kwargs)
           ^^^^^^^^^^^^^^^^^^^^^^^^^^^^^^^^^^^^^^^^^^^^^^^^^^^^^
  File "/opt/airflow/dags/train.py", line 30, in craw_stock_price
    stock_price_df = stock_price_df.append(stock, ignore_index=True)
                     ^^^^^^^^^^^^^^^^^^^^^
  File "/home/airflow/.local/lib/python3.11/site-packages/pandas/core/generic.py", line 6296, in __getattr__
    return object.__getattribute__(self, name)
           ^^^^^^^^^^^^^^^^^^^^^^^^^^^^^^^^^^^
AttributeError: 'DataFrame' object has no attribute 'append'
[2024-02-27T05:08:30.368+0000] {taskinstance.py:1149} INFO - Marking task as FAILED. dag_id=miai_dag, task_id=crawl_data, execution_date=20240227T050300, start_date=20240227T050818, end_date=20240227T050830
[2024-02-27T05:08:30.378+0000] {logging_mixin.py:188} WARNING - /home/***/.local/lib/python3.11/site-packages/***/utils/email.py:154 RemovedInAirflow3Warning: Fetching SMTP credentials from configuration variables will be deprecated in a future release. Please set credentials using a connection instead.
[2024-02-27T05:08:30.380+0000] {configuration.py:1046} WARNING - section/key [smtp/smtp_user] not found in config
[2024-02-27T05:08:30.381+0000] {email.py:270} INFO - Email alerting: attempt 1
[2024-02-27T05:08:30.389+0000] {configuration.py:1046} WARNING - section/key [smtp/smtp_user] not found in config
[2024-02-27T05:08:30.393+0000] {email.py:270} INFO - Email alerting: attempt 1
[2024-02-27T05:08:30.394+0000] {taskinstance.py:837} ERROR - Failed to send email to: ['phuongthaoadn@gmail.com']
Traceback (most recent call last):
  File "/home/airflow/.local/lib/python3.11/site-packages/airflow/models/taskinstance.py", line 2357, in _run_raw_task
    self._execute_task_with_callbacks(context, test_mode, session=session)
  File "/home/airflow/.local/lib/python3.11/site-packages/airflow/models/taskinstance.py", line 2529, in _execute_task_with_callbacks
    result = self._execute_task(context, task_orig)
             ^^^^^^^^^^^^^^^^^^^^^^^^^^^^^^^^^^^^^^
  File "/home/airflow/.local/lib/python3.11/site-packages/airflow/models/taskinstance.py", line 2546, in _execute_task
    return _execute_task(self, context, task_orig)
           ^^^^^^^^^^^^^^^^^^^^^^^^^^^^^^^^^^^^^^^
  File "/home/airflow/.local/lib/python3.11/site-packages/airflow/models/taskinstance.py", line 444, in _execute_task
    result = _execute_callable(context=context, **execute_callable_kwargs)
             ^^^^^^^^^^^^^^^^^^^^^^^^^^^^^^^^^^^^^^^^^^^^^^^^^^^^^^^^^^^^^
  File "/home/airflow/.local/lib/python3.11/site-packages/airflow/models/taskinstance.py", line 414, in _execute_callable
    return execute_callable(context=context, **execute_callable_kwargs)
           ^^^^^^^^^^^^^^^^^^^^^^^^^^^^^^^^^^^^^^^^^^^^^^^^^^^^^^^^^^^^
  File "/home/airflow/.local/lib/python3.11/site-packages/airflow/operators/python.py", line 200, in execute
    return_value = self.execute_callable()
                   ^^^^^^^^^^^^^^^^^^^^^^^
  File "/home/airflow/.local/lib/python3.11/site-packages/airflow/operators/python.py", line 217, in execute_callable
    return self.python_callable(*self.op_args, **self.op_kwargs)
           ^^^^^^^^^^^^^^^^^^^^^^^^^^^^^^^^^^^^^^^^^^^^^^^^^^^^^
  File "/opt/airflow/dags/train.py", line 30, in craw_stock_price
    stock_price_df = stock_price_df.append(stock, ignore_index=True)
                     ^^^^^^^^^^^^^^^^^^^^^
  File "/home/airflow/.local/lib/python3.11/site-packages/pandas/core/generic.py", line 6296, in __getattr__
    return object.__getattribute__(self, name)
           ^^^^^^^^^^^^^^^^^^^^^^^^^^^^^^^^^^^
AttributeError: 'DataFrame' object has no attribute 'append'

During handling of the above exception, another exception occurred:

Traceback (most recent call last):
  File "/home/airflow/.local/lib/python3.11/site-packages/airflow/models/taskinstance.py", line 1011, in _email_alert
    send_email(task.email, subject, html_content)
  File "/home/airflow/.local/lib/python3.11/site-packages/airflow/utils/email.py", line 80, in send_email
    return backend(
           ^^^^^^^^
  File "/home/airflow/.local/lib/python3.11/site-packages/airflow/utils/email.py", line 154, in send_email_smtp
    send_mime_email(e_from=mail_from, e_to=recipients, mime_msg=msg, conn_id=conn_id, dryrun=dryrun)
  File "/home/airflow/.local/lib/python3.11/site-packages/airflow/utils/email.py", line 272, in send_mime_email
    smtp_conn = _get_smtp_connection(smtp_host, smtp_port, smtp_timeout, smtp_ssl)
                ^^^^^^^^^^^^^^^^^^^^^^^^^^^^^^^^^^^^^^^^^^^^^^^^^^^^^^^^^^^^^^^^^^
  File "/home/airflow/.local/lib/python3.11/site-packages/airflow/utils/email.py", line 316, in _get_smtp_connection
    return smtplib.SMTP(host=host, port=port, timeout=timeout)
           ^^^^^^^^^^^^^^^^^^^^^^^^^^^^^^^^^^^^^^^^^^^^^^^^^^^
  File "/usr/local/lib/python3.11/smtplib.py", line 255, in __init__
    (code, msg) = self.connect(host, port)
                  ^^^^^^^^^^^^^^^^^^^^^^^^
  File "/usr/local/lib/python3.11/smtplib.py", line 341, in connect
    self.sock = self._get_socket(host, port, self.timeout)
                ^^^^^^^^^^^^^^^^^^^^^^^^^^^^^^^^^^^^^^^^^^
  File "/usr/local/lib/python3.11/smtplib.py", line 312, in _get_socket
    return socket.create_connection((host, port), timeout,
           ^^^^^^^^^^^^^^^^^^^^^^^^^^^^^^^^^^^^^^^^^^^^^^^
  File "/usr/local/lib/python3.11/socket.py", line 851, in create_connection
    raise exceptions[0]
  File "/usr/local/lib/python3.11/socket.py", line 836, in create_connection
    sock.connect(sa)
OSError: [Errno 99] Cannot assign requested address

During handling of the above exception, another exception occurred:

Traceback (most recent call last):
  File "/home/airflow/.local/lib/python3.11/site-packages/airflow/models/taskinstance.py", line 835, in _handle_failure
    task_instance.email_alert(error, failure_context["task"])
  File "/home/airflow/.local/lib/python3.11/site-packages/airflow/models/taskinstance.py", line 2976, in email_alert
    _email_alert(task_instance=self, exception=exception, task=task)
  File "/home/airflow/.local/lib/python3.11/site-packages/airflow/models/taskinstance.py", line 1013, in _email_alert
    send_email(task.email, subject, html_content_err)
  File "/home/airflow/.local/lib/python3.11/site-packages/airflow/utils/email.py", line 80, in send_email
    return backend(
           ^^^^^^^^
  File "/home/airflow/.local/lib/python3.11/site-packages/airflow/utils/email.py", line 154, in send_email_smtp
    send_mime_email(e_from=mail_from, e_to=recipients, mime_msg=msg, conn_id=conn_id, dryrun=dryrun)
  File "/home/airflow/.local/lib/python3.11/site-packages/airflow/utils/email.py", line 272, in send_mime_email
    smtp_conn = _get_smtp_connection(smtp_host, smtp_port, smtp_timeout, smtp_ssl)
                ^^^^^^^^^^^^^^^^^^^^^^^^^^^^^^^^^^^^^^^^^^^^^^^^^^^^^^^^^^^^^^^^^^
  File "/home/airflow/.local/lib/python3.11/site-packages/airflow/utils/email.py", line 316, in _get_smtp_connection
    return smtplib.SMTP(host=host, port=port, timeout=timeout)
           ^^^^^^^^^^^^^^^^^^^^^^^^^^^^^^^^^^^^^^^^^^^^^^^^^^^
  File "/usr/local/lib/python3.11/smtplib.py", line 255, in __init__
    (code, msg) = self.connect(host, port)
                  ^^^^^^^^^^^^^^^^^^^^^^^^
  File "/usr/local/lib/python3.11/smtplib.py", line 341, in connect
    self.sock = self._get_socket(host, port, self.timeout)
                ^^^^^^^^^^^^^^^^^^^^^^^^^^^^^^^^^^^^^^^^^^
  File "/usr/local/lib/python3.11/smtplib.py", line 312, in _get_socket
    return socket.create_connection((host, port), timeout,
           ^^^^^^^^^^^^^^^^^^^^^^^^^^^^^^^^^^^^^^^^^^^^^^^
  File "/usr/local/lib/python3.11/socket.py", line 851, in create_connection
    raise exceptions[0]
  File "/usr/local/lib/python3.11/socket.py", line 836, in create_connection
    sock.connect(sa)
OSError: [Errno 99] Cannot assign requested address
[2024-02-27T05:08:30.409+0000] {standard_task_runner.py:107} ERROR - Failed to execute job 38 for task crawl_data ('DataFrame' object has no attribute 'append'; 1527)
[2024-02-27T05:08:30.447+0000] {local_task_job_runner.py:234} INFO - Task exited with return code 1
[2024-02-27T05:08:30.461+0000] {taskinstance.py:3309} INFO - 0 downstream tasks scheduled from follow-on schedule check
