[2024-02-26T16:41:26.037+0000] {taskinstance.py:1979} INFO - Dependencies all met for dep_context=non-requeueable deps ti=<TaskInstance: thaocodon.print_date manual__2024-02-26T16:40:23.496524+00:00 [queued]>
[2024-02-26T16:41:26.043+0000] {taskinstance.py:1979} INFO - Dependencies all met for dep_context=requeueable deps ti=<TaskInstance: thaocodon.print_date manual__2024-02-26T16:40:23.496524+00:00 [queued]>
[2024-02-26T16:41:26.045+0000] {taskinstance.py:2193} INFO - Starting attempt 2 of 2
[2024-02-26T16:41:26.053+0000] {taskinstance.py:2214} INFO - Executing <Task(BashOperator): print_date> on 2024-02-26 16:40:23.496524+00:00
[2024-02-26T16:41:26.058+0000] {standard_task_runner.py:60} INFO - Started process 555 to run task
[2024-02-26T16:41:26.062+0000] {standard_task_runner.py:87} INFO - Running: ['***', 'tasks', 'run', 'thaocodon', 'print_date', 'manual__2024-02-26T16:40:23.496524+00:00', '--job-id', '8', '--raw', '--subdir', 'DAGS_FOLDER/thaocodon.py', '--cfg-path', '/tmp/tmp5d7_qzic']
[2024-02-26T16:41:26.065+0000] {standard_task_runner.py:88} INFO - Job 8: Subtask print_date
[2024-02-26T16:41:26.111+0000] {task_command.py:423} INFO - Running <TaskInstance: thaocodon.print_date manual__2024-02-26T16:40:23.496524+00:00 [running]> on host a4c4cdbc324d
[2024-02-26T16:41:26.330+0000] {taskinstance.py:2510} INFO - Exporting env vars: AIRFLOW_CTX_DAG_EMAIL='thangnch@gmail.com' AIRFLOW_CTX_DAG_OWNER='***' AIRFLOW_CTX_DAG_ID='thaocodon' AIRFLOW_CTX_TASK_ID='print_date' AIRFLOW_CTX_EXECUTION_DATE='2024-02-26T16:40:23.496524+00:00' AIRFLOW_CTX_TRY_NUMBER='2' AIRFLOW_CTX_DAG_RUN_ID='manual__2024-02-26T16:40:23.496524+00:00'
[2024-02-26T16:41:26.334+0000] {subprocess.py:63} INFO - Tmp dir root location: /tmp
[2024-02-26T16:41:26.336+0000] {subprocess.py:75} INFO - Running command: ['/usr/bin/bash', '-c', 'date > /home/thangnc/date.txt']
[2024-02-26T16:41:26.346+0000] {subprocess.py:86} INFO - Output:
[2024-02-26T16:41:26.350+0000] {subprocess.py:93} INFO - /usr/bin/bash: line 1: /home/thangnc/date.txt: No such file or directory
[2024-02-26T16:41:26.352+0000] {subprocess.py:97} INFO - Command exited with return code 1
[2024-02-26T16:41:26.373+0000] {taskinstance.py:2728} ERROR - Task failed with exception
Traceback (most recent call last):
  File "/home/airflow/.local/lib/python3.11/site-packages/airflow/models/taskinstance.py", line 444, in _execute_task
    result = _execute_callable(context=context, **execute_callable_kwargs)
             ^^^^^^^^^^^^^^^^^^^^^^^^^^^^^^^^^^^^^^^^^^^^^^^^^^^^^^^^^^^^^
  File "/home/airflow/.local/lib/python3.11/site-packages/airflow/models/taskinstance.py", line 414, in _execute_callable
    return execute_callable(context=context, **execute_callable_kwargs)
           ^^^^^^^^^^^^^^^^^^^^^^^^^^^^^^^^^^^^^^^^^^^^^^^^^^^^^^^^^^^^
  File "/home/airflow/.local/lib/python3.11/site-packages/airflow/operators/bash.py", line 212, in execute
    raise AirflowException(
airflow.exceptions.AirflowException: Bash command failed. The command returned a non-zero exit code 1.
[2024-02-26T16:41:26.378+0000] {taskinstance.py:1149} INFO - Marking task as FAILED. dag_id=thaocodon, task_id=print_date, execution_date=20240226T164023, start_date=20240226T164126, end_date=20240226T164126
[2024-02-26T16:41:26.393+0000] {logging_mixin.py:188} WARNING - /home/***/.local/lib/python3.11/site-packages/***/utils/email.py:154 RemovedInAirflow3Warning: Fetching SMTP credentials from configuration variables will be deprecated in a future release. Please set credentials using a connection instead.
[2024-02-26T16:41:26.396+0000] {configuration.py:1046} WARNING - section/key [smtp/smtp_user] not found in config
[2024-02-26T16:41:26.397+0000] {email.py:270} INFO - Email alerting: attempt 1
[2024-02-26T16:41:26.407+0000] {configuration.py:1046} WARNING - section/key [smtp/smtp_user] not found in config
[2024-02-26T16:41:26.409+0000] {email.py:270} INFO - Email alerting: attempt 1
[2024-02-26T16:41:26.410+0000] {taskinstance.py:837} ERROR - Failed to send email to: ['thangnch@gmail.com']
Traceback (most recent call last):
  File "/home/airflow/.local/lib/python3.11/site-packages/airflow/models/taskinstance.py", line 2357, in _run_raw_task
    self._execute_task_with_callbacks(context, test_mode, session=session)
  File "/home/airflow/.local/lib/python3.11/site-packages/airflow/models/taskinstance.py", line 2529, in _execute_task_with_callbacks
    result = self._execute_task(context, task_orig)
             ^^^^^^^^^^^^^^^^^^^^^^^^^^^^^^^^^^^^^^
  File "/home/airflow/.local/lib/python3.11/site-packages/airflow/models/taskinstance.py", line 2546, in _execute_task
    return _execute_task(self, context, task_orig)
           ^^^^^^^^^^^^^^^^^^^^^^^^^^^^^^^^^^^^^^^
  File "/home/airflow/.local/lib/python3.11/site-packages/airflow/models/taskinstance.py", line 444, in _execute_task
    result = _execute_callable(context=context, **execute_callable_kwargs)
             ^^^^^^^^^^^^^^^^^^^^^^^^^^^^^^^^^^^^^^^^^^^^^^^^^^^^^^^^^^^^^
  File "/home/airflow/.local/lib/python3.11/site-packages/airflow/models/taskinstance.py", line 414, in _execute_callable
    return execute_callable(context=context, **execute_callable_kwargs)
           ^^^^^^^^^^^^^^^^^^^^^^^^^^^^^^^^^^^^^^^^^^^^^^^^^^^^^^^^^^^^
  File "/home/airflow/.local/lib/python3.11/site-packages/airflow/operators/bash.py", line 212, in execute
    raise AirflowException(
airflow.exceptions.AirflowException: Bash command failed. The command returned a non-zero exit code 1.

During handling of the above exception, another exception occurred:

Traceback (most recent call last):
  File "/home/airflow/.local/lib/python3.11/site-packages/airflow/models/taskinstance.py", line 1011, in _email_alert
    send_email(task.email, subject, html_content)
  File "/home/airflow/.local/lib/python3.11/site-packages/airflow/utils/email.py", line 80, in send_email
    return backend(
           ^^^^^^^^
  File "/home/airflow/.local/lib/python3.11/site-packages/airflow/utils/email.py", line 154, in send_email_smtp
    send_mime_email(e_from=mail_from, e_to=recipients, mime_msg=msg, conn_id=conn_id, dryrun=dryrun)
  File "/home/airflow/.local/lib/python3.11/site-packages/airflow/utils/email.py", line 272, in send_mime_email
    smtp_conn = _get_smtp_connection(smtp_host, smtp_port, smtp_timeout, smtp_ssl)
                ^^^^^^^^^^^^^^^^^^^^^^^^^^^^^^^^^^^^^^^^^^^^^^^^^^^^^^^^^^^^^^^^^^
  File "/home/airflow/.local/lib/python3.11/site-packages/airflow/utils/email.py", line 316, in _get_smtp_connection
    return smtplib.SMTP(host=host, port=port, timeout=timeout)
           ^^^^^^^^^^^^^^^^^^^^^^^^^^^^^^^^^^^^^^^^^^^^^^^^^^^
  File "/usr/local/lib/python3.11/smtplib.py", line 255, in __init__
    (code, msg) = self.connect(host, port)
                  ^^^^^^^^^^^^^^^^^^^^^^^^
  File "/usr/local/lib/python3.11/smtplib.py", line 341, in connect
    self.sock = self._get_socket(host, port, self.timeout)
                ^^^^^^^^^^^^^^^^^^^^^^^^^^^^^^^^^^^^^^^^^^
  File "/usr/local/lib/python3.11/smtplib.py", line 312, in _get_socket
    return socket.create_connection((host, port), timeout,
           ^^^^^^^^^^^^^^^^^^^^^^^^^^^^^^^^^^^^^^^^^^^^^^^
  File "/usr/local/lib/python3.11/socket.py", line 851, in create_connection
    raise exceptions[0]
  File "/usr/local/lib/python3.11/socket.py", line 836, in create_connection
    sock.connect(sa)
OSError: [Errno 99] Cannot assign requested address

During handling of the above exception, another exception occurred:

Traceback (most recent call last):
  File "/home/airflow/.local/lib/python3.11/site-packages/airflow/models/taskinstance.py", line 835, in _handle_failure
    task_instance.email_alert(error, failure_context["task"])
  File "/home/airflow/.local/lib/python3.11/site-packages/airflow/models/taskinstance.py", line 2976, in email_alert
    _email_alert(task_instance=self, exception=exception, task=task)
  File "/home/airflow/.local/lib/python3.11/site-packages/airflow/models/taskinstance.py", line 1013, in _email_alert
    send_email(task.email, subject, html_content_err)
  File "/home/airflow/.local/lib/python3.11/site-packages/airflow/utils/email.py", line 80, in send_email
    return backend(
           ^^^^^^^^
  File "/home/airflow/.local/lib/python3.11/site-packages/airflow/utils/email.py", line 154, in send_email_smtp
    send_mime_email(e_from=mail_from, e_to=recipients, mime_msg=msg, conn_id=conn_id, dryrun=dryrun)
  File "/home/airflow/.local/lib/python3.11/site-packages/airflow/utils/email.py", line 272, in send_mime_email
    smtp_conn = _get_smtp_connection(smtp_host, smtp_port, smtp_timeout, smtp_ssl)
                ^^^^^^^^^^^^^^^^^^^^^^^^^^^^^^^^^^^^^^^^^^^^^^^^^^^^^^^^^^^^^^^^^^
  File "/home/airflow/.local/lib/python3.11/site-packages/airflow/utils/email.py", line 316, in _get_smtp_connection
    return smtplib.SMTP(host=host, port=port, timeout=timeout)
           ^^^^^^^^^^^^^^^^^^^^^^^^^^^^^^^^^^^^^^^^^^^^^^^^^^^
  File "/usr/local/lib/python3.11/smtplib.py", line 255, in __init__
    (code, msg) = self.connect(host, port)
                  ^^^^^^^^^^^^^^^^^^^^^^^^
  File "/usr/local/lib/python3.11/smtplib.py", line 341, in connect
    self.sock = self._get_socket(host, port, self.timeout)
                ^^^^^^^^^^^^^^^^^^^^^^^^^^^^^^^^^^^^^^^^^^
  File "/usr/local/lib/python3.11/smtplib.py", line 312, in _get_socket
    return socket.create_connection((host, port), timeout,
           ^^^^^^^^^^^^^^^^^^^^^^^^^^^^^^^^^^^^^^^^^^^^^^^
  File "/usr/local/lib/python3.11/socket.py", line 851, in create_connection
    raise exceptions[0]
  File "/usr/local/lib/python3.11/socket.py", line 836, in create_connection
    sock.connect(sa)
OSError: [Errno 99] Cannot assign requested address
[2024-02-26T16:41:26.430+0000] {standard_task_runner.py:107} ERROR - Failed to execute job 8 for task print_date (Bash command failed. The command returned a non-zero exit code 1.; 555)
[2024-02-26T16:41:26.480+0000] {local_task_job_runner.py:234} INFO - Task exited with return code 1
[2024-02-26T16:41:26.501+0000] {taskinstance.py:3309} INFO - 0 downstream tasks scheduled from follow-on schedule check
